Workbook

Sheet Plan de pruebas
A2: Calidad de Software · Las instancias Team | G2: Plan de pruebas de calidad Aplicación RiTech SAS Marketplace
A3: Marketplace de café y cacao de Nariño para compradores de la Unión Europea
A4: Versión del plan: 29/09/2026 · leyenda en la hoja «Leyenda» | F4: Integrantes del equipo de trabajo: | G4: Nicolas Diaz | H4: Jenifer Urbano | I4: Juan Camilo Lopez
A6: identificador de test | B6: tipo (unitario, de integracion, del sistema …) | C6: responsable | D6: descripcion | E6: Origen del codigo: Nombre de la funcion/metodo/modulo/programa/clase | F6: datos de entrada | G6: resultado esperado | H6: resultado obtenido | I6: Pasa SI/No | J6: fecha del test | K6: Siguiente paso | L6: Ámbito | M6: Trazabilidad (RF / RNF / RN / historia) | N6: Sprint
A7: QA-001 | B7: unitario | C7: Juan Camilo Lopez | D7: Registro de usuario con rol asignado | E7: usuarios/models.py, UsuarioSerializer | F7: nombre, identificación, email, firma, rol=comprador | G7: Usuario creado con rol correcto y estado ACTIVO | H7: Pendiente de ejecución | I7: PENDIENTE | K7: Ejecutar en el Sprint 1 al implementar el módulo en Django (caso del plan del Sprint 2). | L7: Plataforma (Django + PostgreSQL/PostGIS + AWS) | M7: RF-01; LIT-64 | N7: 1
A8: QA-002 | B8: unitario | C8: Nicolas Diaz | D8: Login correcto y rechazo de credenciales inválidas | E8: usuarios/services.py, autenticar() | F8: email/password válidos e inválidos | G8: Acceso con credenciales válidas; 401 con inválidas | H8: Pendiente de ejecución | I8: PENDIENTE | K8: Ejecutar en el Sprint 1 al implementar el módulo en Django (caso del plan del Sprint 2). | L8: Plataforma (Django + PostgreSQL/PostGIS + AWS) | M8: RF-01; LIT-64 | N8: 1
A9: QA-003 | B9: unitario | C9: Jenifer Urbano | D9: Autorización por rol (acceso denegado) | E9: usuarios/permissions.py | F9: comprador intenta acceder a endpoint de admin | G9: HTTP 403; no ejecuta la acción | H9: Pendiente de ejecución | I9: PENDIENTE | K9: Ejecutar en el Sprint 1 al implementar el módulo en Django (caso del plan del Sprint 2). | L9: Plataforma (Django + PostgreSQL/PostGIS + AWS) | M9: RF-01; RNF-05; LIT-64 | N9: 1
A10: QA-004 | B10: unitario | C10: Juan Camilo Lopez | D10: Bloqueo/baneo de usuario por fraude | E10: usuarios/services.py, bloquear() | F10: usuario activo + motivo de fraude | G10: Usuario pasa a BLOQUEADO y no puede iniciar sesión | H10: Pendiente de ejecución | I10: PENDIENTE | K10: Ejecutar en el Sprint 1 al implementar el módulo en Django (caso del plan del Sprint 2). | L10: Plataforma (Django + PostgreSQL/PostGIS + AWS) | M10: RF-04; RN-12; LIT-67 | N10: 1
A11: QA-005 | B11: de integración | C11: Juan Camilo Lopez | D11: Privacidad: un usuario no ve datos privados de otro | E11: fincas/views.py, marketplace/views.py | F11: usuario A solicita ubicación de finca de usuario B | G11: La ubicación permanece oculta (RN-13) | H11: Pendiente de ejecución | I11: PENDIENTE | K11: Ejecutar en el Sprint 1 al implementar el módulo en Django (caso del plan del Sprint 2). | L11: Plataforma (Django + PostgreSQL/PostGIS + AWS) | M11: RF-03; RN-13; RNF-09; LIT-66 | N11: 1
A12: QA-006 | B12: de integración | C12: Nicolas Diaz | D12: Verificación de identidad (identificación + firma) | E12: usuarios/services.py, verificar_identidad() | F12: identificación y firma registradas una sola vez | G12: Identidad verificada; habilita operaciones | H12: Pendiente de ejecución | I12: PENDIENTE | K12: Ejecutar en el Sprint 1 al implementar el módulo en Django (caso del plan del Sprint 2). | L12: Plataforma (Django + PostgreSQL/PostGIS + AWS) | M12: RF-02; RN-5; LIT-65 | N12: 1
A13: QA-007 | B13: de integración | C13: Jenifer Urbano | D13: Bloquear y desbloquear un usuario por intento de fraude. | E13: src/store/DemoStore.tsx, reducer: setUserStatus | F13: administrador bloquea y luego desbloquea a u-buyer2 | G13: Estado 'bloqueado' y luego 'activo', cada acción con su entrada de auditoría (RN-12) | H13: Bloquear → "blocked" (auditoría "block"); desbloquear → "active" (auditoría "unblock") | I13: SI | J13: 46294 | K13: Ejecutado automáticamente (pruebas/ejecutar.mjs). El responsable debe re-ejecutarlo y confirmar. | L13: Prototipo React (demo estática) | M13: RF-04; RN-12; RNF-11; LIT-67 | N13: 1
A14: QA-008 | B14: de integración | C14: Jenifer Urbano | D14: Verificar la identidad de un usuario. | E14: src/store/DemoStore.tsx, reducer: verifyUser | F14: administrador verifica a u-buyer4 (no verificado) | G14: El usuario queda verificado y la acción queda auditada (RF-02) | H14: u-buyer4 verificado: false → true; auditoría "verify" | I14: SI | J14: 46294 | K14: Ejecutado automáticamente (pruebas/ejecutar.mjs). El responsable debe re-ejecutarlo y confirmar. | L14: Prototipo React (demo estática) | M14: RF-02; LIT-65 | N14: 1
A15: QA-009 | B15: de integración | C15: Juan Camilo Lopez | D15: Comprobar que la tarjeta de lote del catálogo no revela la finca ni su ubicación. | E15: src/components/common/LotCard.tsx + I18nProvider (renderToString) | F15: los 9 lotes de ejemplo y un lote de control con la finca en el texto | G15: Ninguna tarjeta muestra nombre de finca, municipio, altitud ni coordenadas (RN-13); el control sí se detecta | H15: 9 tarjetas renderizadas; ninguna muestra nombre de finca, municipio, altitud ni coordenadas; control positivo detectado: sí | I15: SI | J15: 46294 | K15: Ejecutado automáticamente (pruebas/ejecutar.mjs). El responsable debe re-ejecutarlo y confirmar. | L15: Prototipo React (demo estática) | M15: RF-03; RN-13; RNF-09; LIT-66 | N15: 1
A16: QA-010 | B16: del sistema | C16: Jenifer Urbano | D16: Ingresar con cada uno de los 6 roles y revisar su menú. | E16: src/pages/Login.tsx, src/components/layout/roleNav.ts, AppLayout | F16: comprador, vendedor, propietario, transportador, admin. sistema, admin. técnico | G16: Cada rol entra a su panel y ve solo su navegación (RF-01) | H16: Pendiente de ejecución | I16: PENDIENTE | K16: Ejecutar manualmente sobre el prototipo (npm run dev) y adjuntar pantallazos como evidencia. | L16: Prototipo React (demo estática) | M16: RF-01; LIT-64 | N16: 1
A17: QA-011 | B17: del sistema | C17: Nicolas Diaz | D17: Operar la negociación como comprador bloqueado. | E17: src/pages/shared/Negotiations.tsx | F17: negociación abierta con u-buyer3 (bloqueado) | G17: Chat, contraoferta y acuerdo deshabilitados, con aviso visible en texto e ícono (RN-12) | H17: Pendiente de ejecución | I17: PENDIENTE | K17: Ejecutar manualmente sobre el prototipo (npm run dev) y adjuntar pantallazos como evidencia. | L17: Prototipo React (demo estática) | M17: RF-04; RN-12; LIT-67 | N17: 1
A18: QA-012 | B18: del sistema | C18: Jenifer Urbano | D18: Revisar la privacidad en catálogo, detalle de lote y negociación. | E18: src/pages/buyer/Buyer.tsx, src/pages/shared/Negotiations.tsx | F18: lote NAR-2401 visto desde catálogo y desde una negociación activa | G18: Catálogo y detalle solo muestran 'Nariño'; finca, municipio y altitud aparecen únicamente dentro de la negociación (RN-13) | H18: Pendiente de ejecución | I18: PENDIENTE | K18: Ejecutar manualmente sobre el prototipo (npm run dev) y adjuntar pantallazos como evidencia. | L18: Prototipo React (demo estática) | M18: RF-03; RN-13; RNF-09; LIT-66 | N18: 1
A19: QA-013 | B19: unitario | C19: Nicolas Diaz | D19: Impedir modificar nombre, identificación y firma después del registro. | E19: usuarios/serializers.py, UsuarioSerializer | F19: PATCH de identificación y firma de un usuario verificado | G19: Se rechaza la edición: estos datos se ingresan una sola vez (RN-5) | H19: Pendiente de ejecución | I19: PENDIENTE | K19: Ejecutar en el Sprint 1 al implementar el módulo en la plataforma. | L19: Plataforma (Django + PostgreSQL/PostGIS + AWS) | M19: RF-02; RN-5; LIT-65 | N19: 1
A20: FN-001 | B20: unitario | C20: Nicolas Diaz | D20: Registro de finca con polígono PostGIS | E20: fincas/models.py, FincaService | F20: polígono GeoJSON + área | G20: Finca creada con geometry(Polygon,4326) válida | H20: Pendiente de ejecución | I20: PENDIENTE | K20: Ejecutar en el Sprint 2 al implementar el módulo en Django (caso del plan del Sprint 2). | L20: Plataforma (Django + PostgreSQL/PostGIS + AWS) | M20: RF-05; LIT-68 | N20: 2
A21: FN-002 | B21: unitario | C21: Nicolas Diaz | D21: Validación de área de la finca | E21: fincas/validators.py | F21: área negativa / cero / válida | G21: Rechaza áreas inválidas; acepta válidas | H21: Pendiente de ejecución | I21: PENDIENTE | K21: Ejecutar en el Sprint 2 al implementar el módulo en Django (caso del plan del Sprint 2). | L21: Plataforma (Django + PostgreSQL/PostGIS + AWS) | M21: RF-05; RNF-02; LIT-68 | N21: 2
A22: FN-003 | B22: unitario | C22: Juan Camilo Lopez | D22: Validación de origen Colombia/Nariño | E22: fincas/validators.py | F22: coordenadas en Ecuador y en Nariño | G22: Rechaza Ecuador (RN-10); acepta Nariño | H22: Pendiente de ejecución | I22: PENDIENTE | K22: Ejecutar en el Sprint 2 al implementar el módulo en Django (caso del plan del Sprint 2). | L22: Plataforma (Django + PostgreSQL/PostGIS + AWS) | M22: RF-05; RN-2; RN-10; LIT-68 | N22: 2
A23: FN-004 | B23: de integración | C23: Juan Camilo Lopez | D23: Carga de certificado con vigencia | E23: fincas/services.py, CertificadoService | F23: archivo + tipo + fecha de vigencia | G23: Certificado guardado con estado de validación | H23: Pendiente de ejecución | I23: PENDIENTE | K23: Ejecutar en el Sprint 2 al implementar el módulo en Django (caso del plan del Sprint 2). | L23: Plataforma (Django + PostgreSQL/PostGIS + AWS) | M23: RF-06; RN-3; LIT-69 | N23: 2
A24: FN-005 | B24: de integración | C24: Nicolas Diaz | D24: Estado EUDR bloqueado por certificado vencido | E24: fincas/services.py, calcular_eudr() | F24: finca con certificado vencido | G24: estado_eudr = BLOQUEADA; no permite publicar | H24: Pendiente de ejecución | I24: PENDIENTE | K24: Ejecutar en el Sprint 2 al implementar el módulo en Django (caso del plan del Sprint 2). | L24: Plataforma (Django + PostgreSQL/PostGIS + AWS) | M24: RF-06; RF-07; LIT-70 | N24: 2
A25: FN-006 | B25: unitario | C25: Juan Camilo Lopez | D25: Registro del perfil del vendedor | E25: fincas/models.py, PerfilVendedor | F25: capacidad, producto, variedad, calidad | G25: Perfil creado y reutilizable | H25: Pendiente de ejecución | I25: PENDIENTE | K25: Ejecutar en el Sprint 2 al implementar el módulo en Django (caso del plan del Sprint 2). | L25: Plataforma (Django + PostgreSQL/PostGIS + AWS) | M25: RF-08; LIT-71 | N25: 2
A26: FN-007 | B26: de integración | C26: Jenifer Urbano | D26: Registrar una finca nueva con su polígono. | E26: src/store/DemoStore.tsx, reducer: registerFarm | F26: Finca Prueba, Sandoná, 1.800 m, 3,5 ha, polígono de 3 vértices | G26: Finca creada con su polígono y área, en estado EUDR 'pendiente' hasta validar certificados | H26: Finca "Finca Prueba" creada con 3 vértices, 3.5 ha, estado EUDR "pending" | I26: SI | J26: 46294 | K26: Ejecutado automáticamente (pruebas/ejecutar.mjs). El responsable debe re-ejecutarlo y confirmar. | L26: Prototipo React (demo estática) | M26: RF-05; RF-07; LIT-68 | N26: 2
A27: FN-008 | B27: de integración | C27: Juan Camilo Lopez | D27: Habilitar la finca (EUDR) al validar origen y no deforestación. | E27: src/store/DemoStore.tsx, reducer: uploadCertificate + reviewCertificate (recomputeEudr) | F27: certificados de origen y no deforestación vigentes hasta 2027 | G27: Cargados sin validar: 'pendiente'; validados ambos: 'habilitada' (RF-07) | H27: Con certificados cargados sin validar: "pending"; tras validar origen y no deforestación: "enabled" | I27: SI | J27: 46294 | K27: Ejecutado automáticamente (pruebas/ejecutar.mjs). El responsable debe re-ejecutarlo y confirmar. | L27: Prototipo React (demo estática) | M27: RF-06; RF-07; RN-2; RN-3; LIT-69; LIT-70 | N27: 2
A28: FN-009 | B28: de integración | C28: Jenifer Urbano | D28: Mantener la finca sin habilitar si un certificado obligatorio se rechaza. | E28: src/store/DemoStore.tsx, reducer: reviewCertificate (recomputeEudr) | F28: origen validado y no deforestación rechazado | G28: La finca no queda habilitada para publicar | H28: Origen validado + no deforestación rechazado → EUDR "pending" | I28: SI | J28: 46294 | K28: Ejecutado automáticamente (pruebas/ejecutar.mjs). El responsable debe re-ejecutarlo y confirmar. | L28: Prototipo React (demo estática) | M28: RF-06; RF-07; LIT-70 | N28: 2
A29: FN-010 | B29: de integración | C29: Juan Camilo Lopez | D29: No habilitar una finca con certificados vencidos. | E29: src/store/DemoStore.tsx, reducer: reviewCertificate (recomputeEudr) | F29: certificados validados con vigencia 31/01/2026 y 31/03/2026 (vencidos) | G29: La finca no queda habilitada: los certificados deben tener vigencia (RF-06; mismo criterio que FN-005) | H29: Certificados vencidos (31/01/2026 y 31/03/2026) validados → EUDR "enabled"; la función recomputeEudr no consulta validUntil | I29: NO | J29: 46294 | K29: Defecto: recomputeEudr() no compara validUntil con la fecha actual. Corregir para que un certificado vencido deje la finca 'pendiente' o 'bloqueada' y volver a ejecutar FN-010 y FN-005. | L29: Prototipo React (demo estática) | M29: RF-06; RF-07; LIT-69; LIT-70 | N29: 2
A30: FN-011 | B30: del sistema | C30: Nicolas Diaz | D30: Registrar una finca con datos inválidos en el formulario por pasos. | E30: src/pages/owner/Owner.tsx, registro de finca | F30: nombre vacío; área 0; altitud vacía; polígono con 2 vértices; latitud 95 | G30: Cada campo muestra su error asociado y no deja avanzar ni guardar (RNF-02) | H30: Pendiente de ejecución | I30: PENDIENTE | K30: Ejecutar manualmente sobre el prototipo (npm run dev) y adjuntar pantallazos como evidencia. | L30: Prototipo React (demo estática) | M30: RF-05; RNF-02; LIT-68 | N30: 2
A31: FN-012 | B31: del sistema | C31: Nicolas Diaz | D31: Cargar un certificado con el componente de arrastrar y soltar. | E31: src/pages/owner/Owner.tsx, Dropzone | F31: PDF de origen con vigencia futura; intento con fecha pasada | G31: El certificado queda 'pendiente de validación'; la fecha pasada no se acepta (RF-06) | H31: Pendiente de ejecución | I31: PENDIENTE | K31: Ejecutar manualmente sobre el prototipo (npm run dev) y adjuntar pantallazos como evidencia. | L31: Prototipo React (demo estática) | M31: RF-06; RN-3; LIT-69 | N31: 2
A32: MK-001 | B32: unitario | C32: Jenifer Urbano | D32: Validación de cantidad mínima de lote (100 kg) | E32: marketplace/validators.py | F32: 99 kg, 100 kg, 150 kg | G32: Rechaza < 100 kg (RN-1); acepta >= 100 kg | H32: Pendiente de ejecución | I32: PENDIENTE | K32: Ejecutar en el Sprint 3 al implementar el módulo en Django (caso del plan del Sprint 2). | L32: Plataforma (Django + PostgreSQL/PostGIS + AWS) | M32: RF-09; RN-1; LIT-72 | N32: 3
A33: MK-002 | B33: unitario | C33: Nicolas Diaz | D33: Modalidad de precio fijo / a acordar | E33: marketplace/models.py, Lote | F33: precio fijo y precio 'a acordar' | G33: Lote creado con la modalidad correcta (RN-4) | H33: Pendiente de ejecución | I33: PENDIENTE | K33: Ejecutar en el Sprint 3 al implementar el módulo en Django (caso del plan del Sprint 2). | L33: Plataforma (Django + PostgreSQL/PostGIS + AWS) | M33: RF-09; RN-4; LIT-72 | N33: 3
A34: MK-003 | B34: unitario | C34: Juan Camilo Lopez | D34: Bloqueo de publicación sin certificados válidos | E34: marketplace/services.py | F34: vendedor con finca BLOQUEADA | G34: No permite publicar el lote | H34: Pendiente de ejecución | I34: PENDIENTE | K34: Ejecutar en el Sprint 3 al implementar el módulo en Django (caso del plan del Sprint 2). | L34: Plataforma (Django + PostgreSQL/PostGIS + AWS) | M34: RF-07; RF-09; LIT-72 | N34: 3
A35: MK-004 | B35: de integración | C35: Jenifer Urbano | D35: Búsqueda y filtros de lotes | E35: marketplace/views.py, filtrar() | F35: producto=café, origen=Nariño, cantidad>=100 | G35: Devuelve solo lotes que cumplen y sin datos privados | H35: Pendiente de ejecución | I35: PENDIENTE | K35: Ejecutar en el Sprint 3 al implementar el módulo en Django (caso del plan del Sprint 2). | L35: Plataforma (Django + PostgreSQL/PostGIS + AWS) | M35: RF-10; RN-13; RNF-07; LIT-73 | N35: 3
A36: MK-005 | B36: de integración | C36: Jenifer Urbano | D36: Chat de negociación comprador-vendedor | E36: marketplace/services.py, NegociacionService | F36: mensajes entre comprador y vendedor | G36: Mensajes almacenados en orden dentro de la negociación | H36: Pendiente de ejecución | I36: PENDIENTE | K36: Ejecutar en el Sprint 3 al implementar el módulo en Django (caso del plan del Sprint 2). | L36: Plataforma (Django + PostgreSQL/PostGIS + AWS) | M36: RF-11; LIT-74 | N36: 3
A37: MK-006 | B37: de integración | C37: Nicolas Diaz | D37: Transacción inmutable tras el acuerdo | E37: marketplace/services.py, crear_transaccion() | F37: intento de editar transacción acordada | G37: Cambio rechazado (RN-6); requiere disputa | H37: Pendiente de ejecución | I37: PENDIENTE | K37: Ejecutar en el Sprint 3 al implementar el módulo en Django (caso del plan del Sprint 2). | L37: Plataforma (Django + PostgreSQL/PostGIS + AWS) | M37: RF-12; RN-6; RNF-03; LIT-75 | N37: 3
A38: MK-007 | B38: unitario | C38: Juan Camilo Lopez | D38: Validar la cantidad mínima de un lote en el límite de 100 kg. | E38: src/domain/rules.ts, validateQuantity() | F38: 99 kg, 100 kg y 150 kg | G38: 99 kg se rechaza por mínimo (RN-1); 100 kg y 150 kg se aceptan | H38: 99 kg → "min"; 100 kg → null; 150 kg → null | I38: SI | J38: 46294 | K38: Ejecutado automáticamente (pruebas/ejecutar.mjs). El responsable debe re-ejecutarlo y confirmar. | L38: Prototipo React (demo estática) | M38: RF-09; RN-1; LIT-72 | N38: 3
A39: MK-008 | B39: unitario | C39: Jenifer Urbano | D39: Validar cantidad vacía, no numérica y mayor que la disponible del lote. | E39: src/domain/rules.ts, validateQuantity() | F39: vacío, NaN, 600 kg con 500 disponibles, 500 kg con 500 disponibles | G39: Vacío y NaN: campo requerido; 600 > 500: excede lo disponible; 500 = 500: válido | H39: vacío → "required"; NaN → "required"; 600 con máx. 500 → "exceeds"; 500 con máx. 500 → null | I39: SI | J39: 46294 | K39: Ejecutado automáticamente (pruebas/ejecutar.mjs). El responsable debe re-ejecutarlo y confirmar. | L39: Prototipo React (demo estática) | M39: RF-09; RNF-02; LIT-72 | N39: 3
A40: MK-009 | B40: de integración | C40: Jenifer Urbano | D40: Publicar un lote y registrarlo en la auditoría. | E40: src/store/DemoStore.tsx, reducer: publishLot | F40: vendedor publica 300 kg de Castillo a 7 €/kg (negociable) | G40: Lote nuevo con código consecutivo NAR-n, estado publicado y entrada de auditoría del vendedor | H40: Lote NAR-2410 (published); lotes 9 → 10; auditoría "publish" por u-seller | I40: SI | J40: 46294 | K40: Ejecutado automáticamente (pruebas/ejecutar.mjs). El responsable debe re-ejecutarlo y confirmar. | L40: Prototipo React (demo estática) | M40: RF-09; RNF-11; LIT-72 | N40: 3
A41: MK-010 | B41: de integración | C41: Jenifer Urbano | D41: Iniciar una negociación sobre un lote publicado. | E41: src/store/DemoStore.tsx, reducer: startNegotiation | F41: comprador abre negociación del lote publicado | G41: Negociación abierta con la oferta inicial igual al precio y cantidad del lote; el lote pasa a 'en negociación' | H41: Negociación open; oferta inicial 7 €/kg × 300 kg; lote pasa a "negotiating" | I41: SI | J41: 46294 | K41: Ejecutado automáticamente (pruebas/ejecutar.mjs). El responsable debe re-ejecutarlo y confirmar. | L41: Prototipo React (demo estática) | M41: RF-11; LIT-74 | N41: 3
A42: MK-011 | B42: de integración | C42: Juan Camilo Lopez | D42: Enviar mensajes en el chat de negociación y conservar su orden. | E42: src/store/DemoStore.tsx, reducer: sendMessage | F42: 3 mensajes alternados comprador / vendedor | G42: Los 3 mensajes quedan en la negociación en el orden en que se enviaron | H42: 3 mensajes en orden: u-buyer, u-seller, u-buyer | I42: SI | J42: 46294 | K42: Ejecutado automáticamente (pruebas/ejecutar.mjs). El responsable debe re-ejecutarlo y confirmar. | L42: Prototipo React (demo estática) | M42: RF-11; LIT-74 | N42: 3
...

Sheet Resumen
A1: Resumen del plan de pruebas
A2: Todas las cifras son fórmulas sobre la hoja «Plan de pruebas».
A4: Por módulo
A5: Módulo | B5: Casos | C5: Ejecutados | D5: Pasan (SI) | E5: Fallan (NO) | F5: Pendientes | G5: % que pasa de los ejecutados
A6: QA · Usuarios y seguridad | B6: =COUNTIFS('Plan de pruebas'!$A$7:$A$108,"QA-*") | C6: =D6+E6 | D6: =COUNTIFS('Plan de pruebas'!$A$7:$A$108,"QA-*",'Plan de pruebas'!$I$7:$I$108,"SI") | E6: =COUNTIFS('Plan de pruebas'!$A$7:$A$108,"QA-*",'Plan de pruebas'!$I$7:$I$108,"NO") | F6: =COUNTIFS('Plan de pruebas'!$A$7:$A$108,"QA-*",'Plan de pruebas'!$I$7:$I$108,"PENDIENTE") | G6: =IF(C6=0,"-",D6/C6)
A7: FN · Fincas y trazabilidad EUDR | B7: =COUNTIFS('Plan de pruebas'!$A$7:$A$108,"FN-*") | C7: =D7+E7 | D7: =COUNTIFS('Plan de pruebas'!$A$7:$A$108,"FN-*",'Plan de pruebas'!$I$7:$I$108,"SI") | E7: =COUNTIFS('Plan de pruebas'!$A$7:$A$108,"FN-*",'Plan de pruebas'!$I$7:$I$108,"NO") | F7: =COUNTIFS('Plan de pruebas'!$A$7:$A$108,"FN-*",'Plan de pruebas'!$I$7:$I$108,"PENDIENTE") | G7: =IF(C7=0,"-",D7/C7)
A8: MK · Marketplace | B8: =COUNTIFS('Plan de pruebas'!$A$7:$A$108,"MK-*") | C8: =D8+E8 | D8: =COUNTIFS('Plan de pruebas'!$A$7:$A$108,"MK-*",'Plan de pruebas'!$I$7:$I$108,"SI") | E8: =COUNTIFS('Plan de pruebas'!$A$7:$A$108,"MK-*",'Plan de pruebas'!$I$7:$I$108,"NO") | F8: =COUNTIFS('Plan de pruebas'!$A$7:$A$108,"MK-*",'Plan de pruebas'!$I$7:$I$108,"PENDIENTE") | G8: =IF(C8=0,"-",D8/C8)
A9: TX · Transacciones y escrow | B9: =COUNTIFS('Plan de pruebas'!$A$7:$A$108,"TX-*") | C9: =D9+E9 | D9: =COUNTIFS('Plan de pruebas'!$A$7:$A$108,"TX-*",'Plan de pruebas'!$I$7:$I$108,"SI") | E9: =COUNTIFS('Plan de pruebas'!$A$7:$A$108,"TX-*",'Plan de pruebas'!$I$7:$I$108,"NO") | F9: =COUNTIFS('Plan de pruebas'!$A$7:$A$108,"TX-*",'Plan de pruebas'!$I$7:$I$108,"PENDIENTE") | G9: =IF(C9=0,"-",D9/C9)
A10: CL · Calidad | B10: =COUNTIFS('Plan de pruebas'!$A$7:$A$108,"CL-*") | C10: =D10+E10 | D10: =COUNTIFS('Plan de pruebas'!$A$7:$A$108,"CL-*",'Plan de pruebas'!$I$7:$I$108,"SI") | E10: =COUNTIFS('Plan de pruebas'!$A$7:$A$108,"CL-*",'Plan de pruebas'!$I$7:$I$108,"NO") | F10: =COUNTIFS('Plan de pruebas'!$A$7:$A$108,"CL-*",'Plan de pruebas'!$I$7:$I$108,"PENDIENTE") | G10: =IF(C10=0,"-",D10/C10)
A11: LG · Logística (tracker) | B11: =COUNTIFS('Plan de pruebas'!$A$7:$A$108,"LG-*") | C11: =D11+E11 | D11: =COUNTIFS('Plan de pruebas'!$A$7:$A$108,"LG-*",'Plan de pruebas'!$I$7:$I$108,"SI") | E11: =COUNTIFS('Plan de pruebas'!$A$7:$A$108,"LG-*",'Plan de pruebas'!$I$7:$I$108,"NO") | F11: =COUNTIFS('Plan de pruebas'!$A$7:$A$108,"LG-*",'Plan de pruebas'!$I$7:$I$108,"PENDIENTE") | G11: =IF(C11=0,"-",D11/C11)
A12: AD · Administración | B12: =COUNTIFS('Plan de pruebas'!$A$7:$A$108,"AD-*") | C12: =D12+E12 | D12: =COUNTIFS('Plan de pruebas'!$A$7:$A$108,"AD-*",'Plan de pruebas'!$I$7:$I$108,"SI") | E12: =COUNTIFS('Plan de pruebas'!$A$7:$A$108,"AD-*",'Plan de pruebas'!$I$7:$I$108,"NO") | F12: =COUNTIFS('Plan de pruebas'!$A$7:$A$108,"AD-*",'Plan de pruebas'!$I$7:$I$108,"PENDIENTE") | G12: =IF(C12=0,"-",D12/C12)
A13: BD · Base de datos | B13: =COUNTIFS('Plan de pruebas'!$A$7:$A$108,"BD-*") | C13: =D13+E13 | D13: =COUNTIFS('Plan de pruebas'!$A$7:$A$108,"BD-*",'Plan de pruebas'!$I$7:$I$108,"SI") | E13: =COUNTIFS('Plan de pruebas'!$A$7:$A$108,"BD-*",'Plan de pruebas'!$I$7:$I$108,"NO") | F13: =COUNTIFS('Plan de pruebas'!$A$7:$A$108,"BD-*",'Plan de pruebas'!$I$7:$I$108,"PENDIENTE") | G13: =IF(C13=0,"-",D13/C13)
A14: DP · Despliegue y compilación | B14: =COUNTIFS('Plan de pruebas'!$A$7:$A$108,"DP-*") | C14: =D14+E14 | D14: =COUNTIFS('Plan de pruebas'!$A$7:$A$108,"DP-*",'Plan de pruebas'!$I$7:$I$108,"SI") | E14: =COUNTIFS('Plan de pruebas'!$A$7:$A$108,"DP-*",'Plan de pruebas'!$I$7:$I$108,"NO") | F14: =COUNTIFS('Plan de pruebas'!$A$7:$A$108,"DP-*",'Plan de pruebas'!$I$7:$I$108,"PENDIENTE") | G14: =IF(C14=0,"-",D14/C14)
A15: RNF · Requisitos no funcionales | B15: =COUNTIFS('Plan de pruebas'!$A$7:$A$108,"RNF-*") | C15: =D15+E15 | D15: =COUNTIFS('Plan de pruebas'!$A$7:$A$108,"RNF-*",'Plan de pruebas'!$I$7:$I$108,"SI") | E15: =COUNTIFS('Plan de pruebas'!$A$7:$A$108,"RNF-*",'Plan de pruebas'!$I$7:$I$108,"NO") | F15: =COUNTIFS('Plan de pruebas'!$A$7:$A$108,"RNF-*",'Plan de pruebas'!$I$7:$I$108,"PENDIENTE") | G15: =IF(C15=0,"-",D15/C15)
A16: AC · Aceptación (flujo completo) | B16: =COUNTIFS('Plan de pruebas'!$A$7:$A$108,"AC-*") | C16: =D16+E16 | D16: =COUNTIFS('Plan de pruebas'!$A$7:$A$108,"AC-*",'Plan de pruebas'!$I$7:$I$108,"SI") | E16: =COUNTIFS('Plan de pruebas'!$A$7:$A$108,"AC-*",'Plan de pruebas'!$I$7:$I$108,"NO") | F16: =COUNTIFS('Plan de pruebas'!$A$7:$A$108,"AC-*",'Plan de pruebas'!$I$7:$I$108,"PENDIENTE") | G16: =IF(C16=0,"-",D16/C16)
A17: Total | B17: =SUM(B6:B16) | C17: =SUM(C6:C16) | D17: =SUM(D6:D16) | E17: =SUM(E6:E16) | F17: =SUM(F6:F16) | G17: =IF(C17=0,"-",D17/C17)
A19: Por tipo de prueba
A20: Tipo | B20: Casos | C20: Ejecutados | D20: Pasan (SI) | E20: Fallan (NO) | F20: Pendientes | G20: % que pasa de los ejecutados
A21: unitario | B21: =COUNTIFS('Plan de pruebas'!$B$7:$B$108,"unitario") | C21: =D21+E21 | D21: =COUNTIFS('Plan de pruebas'!$B$7:$B$108,"unitario",'Plan de pruebas'!$I$7:$I$108,"SI") | E21: =COUNTIFS('Plan de pruebas'!$B$7:$B$108,"unitario",'Plan de pruebas'!$I$7:$I$108,"NO") | F21: =COUNTIFS('Plan de pruebas'!$B$7:$B$108,"unitario",'Plan de pruebas'!$I$7:$I$108,"PENDIENTE") | G21: =IF(C21=0,"-",D21/C21)
A22: de integración | B22: =COUNTIFS('Plan de pruebas'!$B$7:$B$108,"de integración") | C22: =D22+E22 | D22: =COUNTIFS('Plan de pruebas'!$B$7:$B$108,"de integración",'Plan de pruebas'!$I$7:$I$108,"SI") | E22: =COUNTIFS('Plan de pruebas'!$B$7:$B$108,"de integración",'Plan de pruebas'!$I$7:$I$108,"NO") | F22: =COUNTIFS('Plan de pruebas'!$B$7:$B$108,"de integración",'Plan de pruebas'!$I$7:$I$108,"PENDIENTE") | G22: =IF(C22=0,"-",D22/C22)
A23: del sistema | B23: =COUNTIFS('Plan de pruebas'!$B$7:$B$108,"del sistema") | C23: =D23+E23 | D23: =COUNTIFS('Plan de pruebas'!$B$7:$B$108,"del sistema",'Plan de pruebas'!$I$7:$I$108,"SI") | E23: =COUNTIFS('Plan de pruebas'!$B$7:$B$108,"del sistema",'Plan de pruebas'!$I$7:$I$108,"NO") | F23: =COUNTIFS('Plan de pruebas'!$B$7:$B$108,"del sistema",'Plan de pruebas'!$I$7:$I$108,"PENDIENTE") | G23: =IF(C23=0,"-",D23/C23)
A24: de aceptación | B24: =COUNTIFS('Plan de pruebas'!$B$7:$B$108,"de aceptación") | C24: =D24+E24 | D24: =COUNTIFS('Plan de pruebas'!$B$7:$B$108,"de aceptación",'Plan de pruebas'!$I$7:$I$108,"SI") | E24: =COUNTIFS('Plan de pruebas'!$B$7:$B$108,"de aceptación",'Plan de pruebas'!$I$7:$I$108,"NO") | F24: =COUNTIFS('Plan de pruebas'!$B$7:$B$108,"de aceptación",'Plan de pruebas'!$I$7:$I$108,"PENDIENTE") | G24: =IF(C24=0,"-",D24/C24)
A25: Total | B25: =SUM(B21:B24) | C25: =SUM(C21:C24) | D25: =SUM(D21:D24) | E25: =SUM(E21:E24) | F25: =SUM(F21:F24) | G25: =IF(C25=0,"-",D25/C25)
A27: Por responsable
A28: Responsable | B28: Casos | C28: Ejecutados | D28: Pasan (SI) | E28: Fallan (NO) | F28: Pendientes | G28: % que pasa de los ejecutados
A29: Nicolas Diaz | B29: =COUNTIFS('Plan de pruebas'!$C$7:$C$108,"Nicolas Diaz") | C29: =D29+E29 | D29: =COUNTIFS('Plan de pruebas'!$C$7:$C$108,"Nicolas Diaz",'Plan de pruebas'!$I$7:$I$108,"SI") | E29: =COUNTIFS('Plan de pruebas'!$C$7:$C$108,"Nicolas Diaz",'Plan de pruebas'!$I$7:$I$108,"NO") | F29: =COUNTIFS('Plan de pruebas'!$C$7:$C$108,"Nicolas Diaz",'Plan de pruebas'!$I$7:$I$108,"PENDIENTE") | G29: =IF(C29=0,"-",D29/C29)
A30: Jenifer Urbano | B30: =COUNTIFS('Plan de pruebas'!$C$7:$C$108,"Jenifer Urbano") | C30: =D30+E30 | D30: =COUNTIFS('Plan de pruebas'!$C$7:$C$108,"Jenifer Urbano",'Plan de pruebas'!$I$7:$I$108,"SI") | E30: =COUNTIFS('Plan de pruebas'!$C$7:$C$108,"Jenifer Urbano",'Plan de pruebas'!$I$7:$I$108,"NO") | F30: =COUNTIFS('Plan de pruebas'!$C$7:$C$108,"Jenifer Urbano",'Plan de pruebas'!$I$7:$I$108,"PENDIENTE") | G30: =IF(C30=0,"-",D30/C30)
A31: Juan Camilo Lopez | B31: =COUNTIFS('Plan de pruebas'!$C$7:$C$108,"Juan Camilo Lopez") | C31: =D31+E31 | D31: =COUNTIFS('Plan de pruebas'!$C$7:$C$108,"Juan Camilo Lopez",'Plan de pruebas'!$I$7:$I$108,"SI") | E31: =COUNTIFS('Plan de pruebas'!$C$7:$C$108,"Juan Camilo Lopez",'Plan de pruebas'!$I$7:$I$108,"NO") | F31: =COUNTIFS('Plan de pruebas'!$C$7:$C$108,"Juan Camilo Lopez",'Plan de pruebas'!$I$7:$I$108,"PENDIENTE") | G31: =IF(C31=0,"-",D31/C31)
A32: Total | B32: =SUM(B29:B31) | C32: =SUM(C29:C31) | D32: =SUM(D29:D31) | E32: =SUM(E29:E31) | F32: =SUM(F29:F31) | G32: =IF(C32=0,"-",D32/C32)
A34: Por ámbito
A35: Ámbito | B35: Casos | C35: Ejecutados | D35: Pasan (SI) | E35: Fallan (NO) | F35: Pendientes | G35: % que pasa de los ejecutados
A36: Prototipo React (demo estática) | B36: =COUNTIFS('Plan de pruebas'!$L$7:$L$108,"Prototipo React (demo estática)") | C36: =D36+E36 | D36: =COUNTIFS('Plan de pruebas'!$L$7:$L$108,"Prototipo React (demo estática)",'Plan de pruebas'!$I$7:$I$108,"SI") | E36: =COUNTIFS('Plan de pruebas'!$L$7:$L$108,"Prototipo React (demo estática)",'Plan de pruebas'!$I$7:$I$108,"NO") | F36: =COUNTIFS('Plan de pruebas'!$L$7:$L$108,"Prototipo React (demo estática)",'Plan de pruebas'!$I$7:$I$108,"PENDIENTE") | G36: =IF(C36=0,"-",D36/C36)
A37: Plataforma (Django + PostgreSQL/PostGIS + AWS) | B37: =COUNTIFS('Plan de pruebas'!$L$7:$L$108,"Plataforma (Django + PostgreSQL/PostGIS + AWS)") | C37: =D37+E37 | D37: =COUNTIFS('Plan de pruebas'!$L$7:$L$108,"Plataforma (Django + PostgreSQL/PostGIS + AWS)",'Plan de pruebas'!$I$7:$I$108,"SI") | E37: =COUNTIFS('Plan de pruebas'!$L$7:$L$108,"Plataforma (Django + PostgreSQL/PostGIS + AWS)",'Plan de pruebas'!$I$7:$I$108,"NO") | F37: =COUNTIFS('Plan de pruebas'!$L$7:$L$108,"Plataforma (Django + PostgreSQL/PostGIS + AWS)",'Plan de pruebas'!$I$7:$I$108,"PENDIENTE") | G37: =IF(C37=0,"-",D37/C37)
A38: Total | B38: =SUM(B36:B37) | C38: =SUM(C36:C37) | D38: =SUM(D36:D37) | E38: =SUM(E36:E37) | F38: =SUM(F36:F37) | G38: =IF(C38=0,"-",D38/C38)

Sheet Trazabilidad
A1: Matriz de trazabilidad: requisitos y reglas de negocio → casos de prueba
A2: Fuente: wiki del proyecto (Requisitos). Cuenta los casos cuya columna M contiene el ID exacto.
A4: ID | B4: Descripción | C4: Casos | D4: Pasan (SI) | E4: Fallan (NO) | F4: Pendientes | G4: Cobertura
A5: RF-01 | B5: Registro y autenticación de usuarios por rol | C5: =SUMPRODUCT(--ISNUMBER(SEARCH("; "&$A5&";","; "&'Plan de pruebas'!$M$7:$M$108&";"))) | D5: =SUMPRODUCT(--ISNUMBER(SEARCH("; "&$A5&";","; "&'Plan de pruebas'!$M$7:$M$108&";")),--('Plan de pruebas'!$I$7:$I$108="SI")) | E5: =SUMPRODUCT(--ISNUMBER(SEARCH("; "&$A5&";","; "&'Plan de pruebas'!$M$7:$M$108&";")),--('Plan de pruebas'!$I$7:$I$108="NO")) | F5: =SUMPRODUCT(--ISNUMBER(SEARCH("; "&$A5&";","; "&'Plan de pruebas'!$M$7:$M$108&";")),--('Plan de pruebas'!$I$7:$I$108="PENDIENTE")) | G5: =IF(C5=0,"SIN CUBRIR",IF(E5>0,"CON FALLAS",IF(D5>0,"VERIFICADO (parcial)","PLANIFICADO")))
A6: RF-02 | B6: Verificación de identidad (identificación y firma una sola vez) | C6: =SUMPRODUCT(--ISNUMBER(SEARCH("; "&$A6&";","; "&'Plan de pruebas'!$M$7:$M$108&";"))) | D6: =SUMPRODUCT(--ISNUMBER(SEARCH("; "&$A6&";","; "&'Plan de pruebas'!$M$7:$M$108&";")),--('Plan de pruebas'!$I$7:$I$108="SI")) | E6: =SUMPRODUCT(--ISNUMBER(SEARCH("; "&$A6&";","; "&'Plan de pruebas'!$M$7:$M$108&";")),--('Plan de pruebas'!$I$7:$I$108="NO")) | F6: =SUMPRODUCT(--ISNUMBER(SEARCH("; "&$A6&";","; "&'Plan de pruebas'!$M$7:$M$108&";")),--('Plan de pruebas'!$I$7:$I$108="PENDIENTE")) | G6: =IF(C6=0,"SIN CUBRIR",IF(E6>0,"CON FALLAS",IF(D6>0,"VERIFICADO (parcial)","PLANIFICADO")))
A7: RF-03 | B7: Ocultar información privada entre usuarios | C7: =SUMPRODUCT(--ISNUMBER(SEARCH("; "&$A7&";","; "&'Plan de pruebas'!$M$7:$M$108&";"))) | D7: =SUMPRODUCT(--ISNUMBER(SEARCH("; "&$A7&";","; "&'Plan de pruebas'!$M$7:$M$108&";")),--('Plan de pruebas'!$I$7:$I$108="SI")) | E7: =SUMPRODUCT(--ISNUMBER(SEARCH("; "&$A7&";","; "&'Plan de pruebas'!$M$7:$M$108&";")),--('Plan de pruebas'!$I$7:$I$108="NO")) | F7: =SUMPRODUCT(--ISNUMBER(SEARCH("; "&$A7&";","; "&'Plan de pruebas'!$M$7:$M$108&";")),--('Plan de pruebas'!$I$7:$I$108="PENDIENTE")) | G7: =IF(C7=0,"SIN CUBRIR",IF(E7>0,"CON FALLAS",IF(D7>0,"VERIFICADO (parcial)","PLANIFICADO")))
A8: RF-04 | B8: Bloqueo y baneo de usuarios por fraude | C8: =SUMPRODUCT(--ISNUMBER(SEARCH("; "&$A8&";","; "&'Plan de pruebas'!$M$7:$M$108&";"))) | D8: =SUMPRODUCT(--ISNUMBER(SEARCH("; "&$A8&";","; "&'Plan de pruebas'!$M$7:$M$108&";")),--('Plan de pruebas'!$I$7:$I$108="SI")) | E8: =SUMPRODUCT(--ISNUMBER(SEARCH("; "&$A8&";","; "&'Plan de pruebas'!$M$7:$M$108&";")),--('Plan de pruebas'!$I$7:$I$108="NO")) | F8: =SUMPRODUCT(--ISNUMBER(SEARCH("; "&$A8&";","; "&'Plan de pruebas'!$M$7:$M$108&";")),--('Plan de pruebas'!$I$7:$I$108="PENDIENTE")) | G8: =IF(C8=0,"SIN CUBRIR",IF(E8>0,"CON FALLAS",IF(D8>0,"VERIFICADO (parcial)","PLANIFICADO")))
A9: RF-05 | B9: Registro de fincas con geolocalización y área | C9: =SUMPRODUCT(--ISNUMBER(SEARCH("; "&$A9&";","; "&'Plan de pruebas'!$M$7:$M$108&";"))) | D9: =SUMPRODUCT(--ISNUMBER(SEARCH("; "&$A9&";","; "&'Plan de pruebas'!$M$7:$M$108&";")),--('Plan de pruebas'!$I$7:$I$108="SI")) | E9: =SUMPRODUCT(--ISNUMBER(SEARCH("; "&$A9&";","; "&'Plan de pruebas'!$M$7:$M$108&";")),--('Plan de pruebas'!$I$7:$I$108="NO")) | F9: =SUMPRODUCT(--ISNUMBER(SEARCH("; "&$A9&";","; "&'Plan de pruebas'!$M$7:$M$108&";")),--('Plan de pruebas'!$I$7:$I$108="PENDIENTE")) | G9: =IF(C9=0,"SIN CUBRIR",IF(E9>0,"CON FALLAS",IF(D9>0,"VERIFICADO (parcial)","PLANIFICADO")))
A10: RF-06 | B10: Carga de certificados de la finca con vigencia | C10: =SUMPRODUCT(--ISNUMBER(SEARCH("; "&$A10&";","; "&'Plan de pruebas'!$M$7:$M$108&";"))) | D10: =SUMPRODUCT(--ISNUMBER(SEARCH("; "&$A10&";","; "&'Plan de pruebas'!$M$7:$M$108&";")),--('Plan de pruebas'!$I$7:$I$108="SI")) | E10: =SUMPRODUCT(--ISNUMBER(SEARCH("; "&$A10&";","; "&'Plan de pruebas'!$M$7:$M$108&";")),--('Plan de pruebas'!$I$7:$I$108="NO")) | F10: =SUMPRODUCT(--ISNUMBER(SEARCH("; "&$A10&";","; "&'Plan de pruebas'!$M$7:$M$108&";")),--('Plan de pruebas'!$I$7:$I$108="PENDIENTE")) | G10: =IF(C10=0,"SIN CUBRIR",IF(E10>0,"CON FALLAS",IF(D10>0,"VERIFICADO (parcial)","PLANIFICADO")))
A11: RF-07 | B11: Estado de cumplimiento EUDR por finca | C11: =SUMPRODUCT(--ISNUMBER(SEARCH("; "&$A11&";","; "&'Plan de pruebas'!$M$7:$M$108&";"))) | D11: =SUMPRODUCT(--ISNUMBER(SEARCH("; "&$A11&";","; "&'Plan de pruebas'!$M$7:$M$108&";")),--('Plan de pruebas'!$I$7:$I$108="SI")) | E11: =SUMPRODUCT(--ISNUMBER(SEARCH("; "&$A11&";","; "&'Plan de pruebas'!$M$7:$M$108&";")),--('Plan de pruebas'!$I$7:$I$108="NO")) | F11: =SUMPRODUCT(--ISNUMBER(SEARCH("; "&$A11&";","; "&'Plan de pruebas'!$M$7:$M$108&";")),--('Plan de pruebas'!$I$7:$I$108="PENDIENTE")) | G11: =IF(C11=0,"SIN CUBRIR",IF(E11>0,"CON FALLAS",IF(D11>0,"VERIFICADO (parcial)","PLANIFICADO")))
A12: RF-08 | B12: Perfil del vendedor | C12: =SUMPRODUCT(--ISNUMBER(SEARCH("; "&$A12&";","; "&'Plan de pruebas'!$M$7:$M$108&";"))) | D12: =SUMPRODUCT(--ISNUMBER(SEARCH("; "&$A12&";","; "&'Plan de pruebas'!$M$7:$M$108&";")),--('Plan de pruebas'!$I$7:$I$108="SI")) | E12: =SUMPRODUCT(--ISNUMBER(SEARCH("; "&$A12&";","; "&'Plan de pruebas'!$M$7:$M$108&";")),--('Plan de pruebas'!$I$7:$I$108="NO")) | F12: =SUMPRODUCT(--ISNUMBER(SEARCH("; "&$A12&";","; "&'Plan de pruebas'!$M$7:$M$108&";")),--('Plan de pruebas'!$I$7:$I$108="PENDIENTE")) | G12: =IF(C12=0,"SIN CUBRIR",IF(E12>0,"CON FALLAS",IF(D12>0,"VERIFICADO (parcial)","PLANIFICADO")))
A13: RF-09 | B13: Publicación de lotes (mínimo 100 kg, precio fijo o a acordar) | C13: =SUMPRODUCT(--ISNUMBER(SEARCH("; "&$A13&";","; "&'Plan de pruebas'!$M$7:$M$108&";"))) | D13: =SUMPRODUCT(--ISNUMBER(SEARCH("; "&$A13&";","; "&'Plan de pruebas'!$M$7:$M$108&";")),--('Plan de pruebas'!$I$7:$I$108="SI")) | E13: =SUMPRODUCT(--ISNUMBER(SEARCH("; "&$A13&";","; "&'Plan de pruebas'!$M$7:$M$108&";")),--('Plan de pruebas'!$I$7:$I$108="NO")) | F13: =SUMPRODUCT(--ISNUMBER(SEARCH("; "&$A13&";","; "&'Plan de pruebas'!$M$7:$M$108&";")),--('Plan de pruebas'!$I$7:$I$108="PENDIENTE")) | G13: =IF(C13=0,"SIN CUBRIR",IF(E13>0,"CON FALLAS",IF(D13>0,"VERIFICADO (parcial)","PLANIFICADO")))
A14: RF-10 | B14: Búsqueda y filtros de lotes | C14: =SUMPRODUCT(--ISNUMBER(SEARCH("; "&$A14&";","; "&'Plan de pruebas'!$M$7:$M$108&";"))) | D14: =SUMPRODUCT(--ISNUMBER(SEARCH("; "&$A14&";","; "&'Plan de pruebas'!$M$7:$M$108&";")),--('Plan de pruebas'!$I$7:$I$108="SI")) | E14: =SUMPRODUCT(--ISNUMBER(SEARCH("; "&$A14&";","; "&'Plan de pruebas'!$M$7:$M$108&";")),--('Plan de pruebas'!$I$7:$I$108="NO")) | F14: =SUMPRODUCT(--ISNUMBER(SEARCH("; "&$A14&";","; "&'Plan de pruebas'!$M$7:$M$108&";")),--('Plan de pruebas'!$I$7:$I$108="PENDIENTE")) | G14: =IF(C14=0,"SIN CUBRIR",IF(E14>0,"CON FALLAS",IF(D14>0,"VERIFICADO (parcial)","PLANIFICADO")))
A15: RF-11 | B15: Chat de negociación | C15: =SUMPRODUCT(--ISNUMBER(SEARCH("; "&$A15&";","; "&'Plan de pruebas'!$M$7:$M$108&";"))) | D15: =SUMPRODUCT(--ISNUMBER(SEARCH("; "&$A15&";","; "&'Plan de pruebas'!$M$7:$M$108&";")),--('Plan de pruebas'!$I$7:$I$108="SI")) | E15: =SUMPRODUCT(--ISNUMBER(SEARCH("; "&$A15&";","; "&'Plan de pruebas'!$M$7:$M$108&";")),--('Plan de pruebas'!$I$7:$I$108="NO")) | F15: =SUMPRODUCT(--ISNUMBER(SEARCH("; "&$A15&";","; "&'Plan de pruebas'!$M$7:$M$108&";")),--('Plan de pruebas'!$I$7:$I$108="PENDIENTE")) | G15: =IF(C15=0,"SIN CUBRIR",IF(E15>0,"CON FALLAS",IF(D15>0,"VERIFICADO (parcial)","PLANIFICADO")))
A16: RF-12 | B16: Transacción de venta inmutable | C16: =SUMPRODUCT(--ISNUMBER(SEARCH("; "&$A16&";","; "&'Plan de pruebas'!$M$7:$M$108&";"))) | D16: =SUMPRODUCT(--ISNUMBER(SEARCH("; "&$A16&";","; "&'Plan de pruebas'!$M$7:$M$108&";")),--('Plan de pruebas'!$I$7:$I$108="SI")) | E16: =SUMPRODUCT(--ISNUMBER(SEARCH("; "&$A16&";","; "&'Plan de pruebas'!$M$7:$M$108&";")),--('Plan de pruebas'!$I$7:$I$108="NO")) | F16: =SUMPRODUCT(--ISNUMBER(SEARCH("; "&$A16&";","; "&'Plan de pruebas'!$M$7:$M$108&";")),--('Plan de pruebas'!$I$7:$I$108="PENDIENTE")) | G16: =IF(C16=0,"SIN CUBRIR",IF(E16>0,"CON FALLAS",IF(D16>0,"VERIFICADO (parcial)","PLANIFICADO")))
... A54: RN-15 | B54: Entregas por módulos y releases mensuales | C54: =SUMPRODUCT(--ISNUMBER(SEARCH("; "&$A54&";","; "&'Plan de pruebas'!$M$7:$M$108&";"))) | D54: =SUMPRODUCT(--ISNUMBER(SEARCH("; "&$A54&";","; "&'Plan de pruebas'!$M$7:$M$108&";")),--('Plan de pruebas'!$I$7:$I$108="SI")) | E54: =SUMPRODUCT(--ISNUMBER(SEARCH("; "&$A54&";","; "&'Plan de pruebas'!$M$7:$M$108&";")),--('Plan de pruebas'!$I$7:$I$108="NO")) | F54: =SUMPRODUCT(--ISNUMBER(SEARCH("; "&$A54&";","; "&'Plan de pruebas'!$M$7:$M$108&";")),--('Plan de pruebas'!$I$7:$I$108="PENDIENTE")) | G54: =IF(C54=0,"SIN CUBRIR",IF(E54>0,"CON FALLAS",IF(D54>0,"VERIFICADO (parcial)","PLANIFICADO")))
A56: Requisitos sin ningún caso: | C56: =COUNTIF(G5:G54,"SIN CUBRIR")
A57: VERIFICADO (parcial): al menos un caso pasó en el prototipo; los casos de la plataforma siguen pendientes.

Sheet Leyenda
A1: Leyenda y criterios del plan
A3: Columnas
A4: identificador de test | B4: Prefijo del módulo + número. Los casos del plan del Sprint 2 conservan su ID (QA, FN y MK 001-006; TX 001-005; CL 001-004; LG, AD, BD y DP 001-002; RNF 001-004); los nuevos continúan la numeración. Ojo: un ID como RNF-011 es un caso de prueba, no el requisito RNF-11; el requisito que cubre cada caso está en la columna Trazabilidad.
A5: tipo | B5: unitario (una función aislada) · de integración (varias piezas juntas: store + reglas, o componente + i18n) · del sistema (la aplicación completa o su compilación) · de aceptación (flujo validado con el Product Owner).
A6: responsable | B6: Asignado al azar y de forma equilibrada entre los tres integrantes (semilla fija para poder reproducir la asignación).
A7: resultado obtenido | B7: Solo se llena con lo que realmente devolvió la ejecución. 'Pendiente de ejecución' si aún no se corre.
A8: Pasa SI/No | B8: SI · NO · PENDIENTE (no ejecutado todavía).
A9: fecha del test | B9: Fecha de la ejecución. Vacía mientras el caso está pendiente.
A10: Ámbito | B10: Prototipo React (demo estática): código que existe hoy en el repositorio. Plataforma (Django + PostgreSQL/PostGIS + AWS): arquitectura objetivo de la wiki, aún no implementada.
A11: Trazabilidad | B11: IDs de la wiki separados por '; ' (RF, RNF, RN) e historias de Jira (LIT). La hoja Trazabilidad los cuenta.
A12: Prefijos de módulo
A13: QA | B13: Usuarios y seguridad (Sprint 1)
A14: FN | B14: Fincas y trazabilidad EUDR (Sprint 2)
A15: MK | B15: Marketplace (Sprint 3)
A16: TX | B16: Transacciones y escrow (Sprint 4)
A17: CL | B17: Calidad (Sprint 5)
A18: LG | B18: Logística (tracker) (Sprint 5)
A19: AD | B19: Administración (Sprint 6)
A20: BD | B20: Base de datos (Sprint 6)
A21: DP | B21: Despliegue y compilación (Sprint 6)
A22: RNF | B22: Requisitos no funcionales (Sprint 6)
A23: AC | B23: Aceptación (flujo completo) (Sprint 1-6)
A24: Cómo se ejecutó
A25: Casos automatizados | B25: 35 casos del prototipo se ejecutaron el 29/09/2026 con `node pruebas/ejecutar.mjs`, que escribe pruebas/resultados.json; `python3 pruebas/generar_excel.py` vuelve a llenar este Excel. El responsable asignado debe re-ejecutarlos y confirmar.
A26: Casos manuales | B26: Los casos del sistema y de aceptación del prototipo se ejecutan con `npm run dev`, recorriendo la interfaz, y se documentan con pantallazos.
A27: Casos de la plataforma | B27: Se ejecutan en el sprint del módulo cuando exista el backend Django + PostgreSQL/PostGIS y la infraestructura AWS.
A28: Supuestos
A29: Comisión mínima | B29: 25 € es un VALOR DE EJEMPLO: el cliente no ha definido la cifra (lo mismo en la interfaz del prototipo).
A30: Rendimiento | B30: El umbral de 2 s (p95) de RNF-013 es una propuesta del equipo; la wiki solo dice 'tiempos aceptables'.
A31: Parámetros de calidad | B31: Los parámetros del laboratorio de la universidad (RN-9) aún no están definidos; CL-002 y CL-009 dependen de ellos.
A32: Fuentes | B32: Wiki: github.com/Jenifrutica/ritech-marketplace/wiki (Requisitos, Arquitectura, Product Backlog, Sprints). Plan del Sprint 2: deliverables/sprint-2/Entregable-B-Plan-de-Pruebas-Sprint2.xlsx.
